<?xml version="1.0" encoding="UTF-8"?>
<robot xmlns:xacro="http://wiki.ros.org/xacro">

  <xacro:include filename="$(find tutorial_robot_1)/urdf/common.xacro" />

  <xacro:macro name="robot_1" params="prefix *origin">

    <!-- BASE LINK -->

    <link name="${prefix}base_link">
    </link>

    <!-- CHASSIS LINK -->

    <link name="${prefix}chassis_link">
      <visual>
        <origin xyz="0.15 0 0.075"/>
        <geometry>
          <box size="0.3 0.3 0.15"/>
        </geometry>
        <xacro:teal_color/>
      </visual>

      <collision>
        <origin xyz="0.15 0 0.075"/>
        <geometry>
          <box size="0.3 0.3 0.15"/>
        </geometry>
      </collision>

      <xacro:box_inertial mass="0.5" x="0.3" y="0.3" z="0.15">
        <origin xyz="0.15 0 0.075" rpy="0 0 0"/>
      </xacro:box_inertial>

    </link>
    
    <joint name="${prefix}chassis_joint" type="fixed">
      <parent link="${prefix}base_link"/>
      <child link="${prefix}chassis_link"/>
      <origin xyz="-0.1 0 0"/>
    </joint>

    <gazebo reference="chassis_link">
      <material>Gazebo/Turquoise</material>
    </gazebo>


    <!-- LEFT WHEEL LINK-->

    <link name="${prefix}left_wheel_link">
      <visual>
        <geometry>
          <cylinder length="0.04" radius="0.05"/> 
        </geometry>
        <xacro:white_color/>
      </visual>

      <xacro:cylinder_inertial mass="0.1" length="0.04" radius="0.05">
        <origin xyz="0 0 0" rpy="0 0 0"/>
      </xacro:cylinder_inertial>

      <collision>
        <geometry>
          <cylinder length="0.04" radius="0.05"/> 
        </geometry>
      </collision>
    </link>

    <joint name="${prefix}left_wheel_joint" type="continuous">
      <parent link="${prefix}base_link"/>
      <child link="${prefix}left_wheel_link"/>
      <origin xyz="0 0.15 0" rpy="${-pi/2} 0 0"/>
      <axis xyz="0 0 1"/>
    </joint>

    <gazebo reference="left_wheel_link">
      <material>Gazebo/White</material>
    </gazebo>

    <!-- RIGHT WHEEL LINK-->

    <link name="${prefix}right_wheel_link">
      <visual>
        <geometry>
          <cylinder length="0.04" radius="0.05"/> 
        </geometry>
        <xacro:white_color/>
      </visual>

      <xacro:cylinder_inertial mass="0.1" length="0.04" radius="0.05">
        <origin xyz="0 0 0" rpy="0 0 0"/>
      </xacro:cylinder_inertial>

      <collision>
        <geometry>
          <cylinder length="0.04" radius="0.05"/> 
        </geometry>
      </collision>
    </link>

    <joint name="${prefix}right_wheel_joint" type="continuous">
      <parent link="${prefix}base_link"/>
      <child link="${prefix}right_wheel_link"/>
      <origin xyz="0 -0.15 0" rpy="${pi/2} 0 0"/>
      <axis xyz="0 0 -1"/>
    </joint>

    <gazebo reference="right_wheel_link">
      <material>Gazebo/White</material>
    </gazebo>

    <!-- CASTER WHEEL LINK -->

    <link name="${prefix}caster_wheel_link">
      <visual>
        <geometry>
          <sphere radius="0.05"/>
        </geometry>
      </visual>

      <xacro:sphere_inertial mass="0.1" radius="0.05">
        <origin xyz="0 0 0" rpy="0 0 0"/>
      </xacro:sphere_inertial>

      <collision>
        <geometry>
          <sphere radius="0.05"/>
        </geometry>
      </collision>
    </link>

    <joint name="${prefix}caster_wheel_joint" type="fixed">
      <parent link="${prefix}chassis_link"/>
      <child link="${prefix}caster_wheel_link"/>
      <origin xyz="0.24 0 0"/>
    </joint>

    <gazebo reference="caster_wheel_link">
      <material>Gazebo/Red</material>
        <mu1 value="0.001"/>
        <mu2 value="0.001"/>      
    </gazebo>



  </xacro:macro>
</robot>

